<!DOCTYPE html>
<html lang="en">
<head>
	<meta charset="UTF-8">
	<title>Promises 对象</title>
</head>
<body>
	<h3>Promise 的含义</h3>
	<p>Promise是异步编程的一种解决方案，比传统的解决方案--回调函数和事件--更合理更强大</p>
	<p>所谓Promise，简单的说就是一个容器，里面保存着某个未来才会结束的事件(通常是一个异步操作)的结果。从语法上说，Promise是一个对象，从它可以获取异步操作的消息。</p>

	<p>Promise对象有两个特点</p>
	<p>1、对象的状态不受外界影响。有三种状态：pending(进行中)、fulfilled(已成功)和rejected(已失败)。只有异步操作的结果，可以决定当前是哪一种状态，任何其他操作都无法改变这个状态。</p>
	<p>2、一旦状态改变，就不会再变，任何时候都可以得到这个结果。Promise对象的状态改变，只有两种可能：pending ==> fulfilled 和 pending ==> rejected。只要这两种情况发生，状态就凝固不会再变了，会一直保持这个结果，称为resolved(已定型)</p>

	<p>有了 Promise 对象，就可以将异步操作以同步操作的流程表达出来，避免了层层嵌套的回调函数。此外，Promise对象提供统一的接口，使得控制异步操作更加容易</p>

	<p>Promise缺点</p>
	<p>1、无法取消；2、如果不设置回调函数，Promise内部抛出的错误不会反应到外部；3、当处于pending状态时，无法得知目前进展到哪一阶段</p>

	<script>
	 	// ES6规定，Promise对象是一个构造函数，用来生成Promise实例，接受两个函数作为参数(reslove, reject)
	 	
	 	const promise = new Promise(function(reslove, reject) {
	 		// ... some code
	 		// if (/* 异步操作成功 */) {
	 		// 	resolve(value);
	 		// } else {
	 		// 	reject(error);
	 		// }
	 	})
	 	// Promise实例生成以后，可以用then方法分别制定resolve状态和rejected状态的回调函数
	 	promise.then(function(value) {
	 		// success
	 	}, function(error) { // 函数是可选的，不一定要提供
	 		// failur
	 	})

	 	// 简单例子
	 	function timeout(ms) {
	 		return new Promise((resolve, reject) => {
	 			setTimeout(resolve, ms, 'done');
	 		})
	 	}
	 	timeout(1000).then((value) => {
	 		console.log(value)
	 	});



	 	// Promise 新建后就会立即执行。首先输出的是Promise，然后，then方法指定的回调函数，将在当前脚本所有同步任务执行完才会执行，所以，resolved最后输出
	 	let p1 = new Promise(function(resolve, reject) {
	 		console.log('Promise');
	 		resolve();
	 	});
	 	p1.then(function() {
	 		console.log('resolved');
	 	});
	 	console.log('Hi!');
	 	// Promise
	 	// Hi!
	 	// resolved


	 	// 异步加载图片的例子
	 	function loadImageAsync(url) {
	 		return new Promise(function(resolve, reject) {
	 			const image = new Image();
	 			image.onload = function() {
	 				resolve(image);
	 			};
	 			image.onerror = function() {
	 				reject(new Error('Could not load image at' + url));
	 			};
	 			image.src = url;
	 		})
	 	}


	 	// Promise 对象实现 Ajax 操作的例子
	 	const getJSON = function(url) {
	 		const promise = new Promise(function(resolve, reject){
	 			const handler = function() {
	 				if (this.readState !== 4){
	 					return;
	 				}
	 				if (this.status === 200) {
	 					resolve(this.response);
	 				} else {
	 					reject(new Error(this.statusText));
	 				}
	 			};
	 			const client = new XMLHttpRequest();
	 			client.open('GET', url);
	 			client.onreadystatuschange = handler;
	 			client.responseType = 'json';
	 			client.setRequestHeader('Accept', 'application/json');
	 			client.send();
	 		});
	 		return promise;
	 	}

	 	// getJSON 是对XMLHttpRequest对象的封装，用于发出一个针对JSON数据的HTTP请求，并且返回一个Promise对象。需要注意的是，在getJSON内部，resolve函数和reject函数调用时，都带有参数
	 	getJSON('/posts.json').then(function(json) {
	 		console.log('Contents:' + json);
	 	}, function(error) {
	 		console.log('出错了', error);
	 	})



	 	// p2和p3都是 Promise 的实例，但是p3的resolve方法将p2作为参数，即一个异步操作的结果是返回另一个异步操作
	 	// p2的状态会传递给p3，也就是说，p2的状态决定了p3的状态。如果p2是pending，那么p3的回调函数就会等待p2的状态改变；如果p2的状态已经是resolved或者rejected，那么p3的回调函数将会立即执行
	 	const p2 = new Promise(function (resolve, reject) {
	 		// ...
	 	});
	 	const p3 = new Promise(function (resolve, reject) {
	 		// ... 
	 		resolve(p2);
	 	})



	 	// p4是一个Promise，3s后变为rejected。p5的状态在1s之后改变，resolve方法返回的是p4。由于p5返回的是另一个Promise，导致p5自己的状态无效了，由p4决定p5的状态。所以后面的then语句都变成针对后者(p4)。又过了2s，p4变为rejected，导致触发catch方法指定的回调函数
	 	const p4 = new Promise(function(resolve, reject) {
	 		setTimeout(() => reject(new Error('fail')), 3000)
	 	})

	 	const p5 = new Promise(function(resolve, reject) {
	 		setTimeout(() => resolve(p4), 1000)
	 	}) 

	 	p5
	 		.then(result => console.log(result))
	 		.catch(error => console.log(error))
	 	// Error: fail




	 	// 定义在Promise原型上的方法
	 	
	 	// 1、Promise.prototype.then()  then方法返回的是一个新的Promise实例(不是原来那个Promise实例)。可采用链式写法，即then方法后面再调用另一个then方法
	 	getJSON('/posts.json').then(function(json) {
	 		return json.post;
	 	}).then(function(post) {
	 		// ...
	 	})
	 	
	 	// 第一个then方法指定的回调函数，返回的是另一个Promise对象。这时，第二个then方法指定的回调函数，就会等待这个新的Promise对象状态发生变化。如果变为resolved，就调用funcA，如果专挑变为rejectd，就调用funcB
	 	getJSON('/post/1.json').then(function(post) {
	 		return getJSON(post.commentURL);
	 	}).then(function funcA(comments) {
	 		console.log('resolved:', comments);
	 	}, function funcB(err) {
	 		console.log('rejected:', err)
	 	})
	 	// 优化 采用箭头函数
	 	getJSON('/post/1.json').then(
	 		post => getJSON(post.commentURL)
	 	).then(
	 		comments => console.log('resolved:', comments),
	 		err => console.log('rejected:', err)
	 	);



	 	// 2、Promise.prototype.catch() 该方法是.then(null, rejection)的别名，用于指定发生错误时的回调函数

	 	getJSON('/posts.json').then(function(posts) {
	 		// ...
	 	}).catch(function(error) {
	 		// 处理 getJSON 和前一个回调函数运行时发生的错误
	 	})

	 	const p6 = new Promise(function(resolve, reject) {
	 		throw new Error('test');
	 	});
	 	p6.catch(function(error) {
	 		console.log(error);
	 	});
	 	// Error: test
	 	// p6与下面两种写法是等价的

	 	// 写法一
	 	const p66 = new Promise(function(resolve, reject) {
	 		try {
	 			throw new Error('test');
	 		} catch(e) {
	 			reject(e);
	 		}
	 	});
	 	p66.catch(function(error) {
	 		console.log(error);
	 	});

	 	// 写法二
	 	const p666 = new Promise(function(resolve, reject) {
	 		reject(new Error('test'));
	 	});
	 	p666 = catch(function(error) {
	 		console.log(error);
	 	});


	 	// 如果 Promise 状态已经变成 resolved, 再抛出错误时无效的
	 	const p7 = new Promise(function(resolve, rejected) {
	 		resolve('ok');
	 		throw new Error('test'); // 抛出错误无效
	 	});
	 	p7
	 		.then(function(value) { console.log(value) })
	 		.catch(function(error) { console.log(error) })
	 	// ok
	 	
	 	// 跟传统的try/catch代码不同的是，如果没有使用catch方法指定错误处理的回调函数，Promise对象抛出的错误不会传递到外层代码，即不会有任何反应
	 	const someAsyncThing = function() {
	 		return new Promise(function(resolve, reject) {
	 			// 下面一行会报错，因为 x 没有声明
	 			resolve(x + 2);
	 		});
	 	};

	 	someAsyncThing().then(function() {
	 		console.log('everything is great');
	 	});
	 	// someAsyncThing函数产生的Promise对象，内部有语法错误。浏览器运行到这一行，会打印错误提示，但是不会退出进程，终止脚本执行，2s后还是会输出123
	 	// 也就是说 Promise 内部的错误不会影响到 Promise 外部代码，通俗的说法就是“Promise 会吃掉错误”

	 	setTimeout(() => { console.log(123) }, 2000);
	 	// Uncaught (in promise) ReferenceError: x is not defined
	 	// 123
	 	

	 	// 一般建议 Promise 对象后面跟 catch 方法，这样可以处理 Promise 内部发生的错误。 catch 方法返回的还是一个 Promise 对象，因此后面还可以接着调用 then 方法
	 	
	 	const p8 = function() {
	 		return new Promise(function(resolve, reject) {
	 			// 下面一行会报错，因为 x 没有声明
	 			resolve(x + 1);
	 		});
	 	};
	 	// 运行完catch方法制定的回调函数，会接着运行后面那个then方法指定的回调函数。如果没有报错，则会跳过catch方法
	 	p8()
	 	.catch(function(error) {
	 		console.log('oh no', error);
	 	})
	 	.then(function() {
	 		console.log('carry on');
	 	});
	 	// oh no [ReferenceError: x is not defined]
	 	// carry on


	 	// catch 方法之中还能再抛出错误。下一级catch会自动捕获上一级catch方法抛出的错误
	 	p8().then(function() {
	 		return p8();
	 	}).catch(function(error) {
	 		console.log('oh no', error);
	 		// 下面一行会报错，因为y没有声明
	 		y + 2;
	 	}).catch(function(error) {
	 		console.log('carry on', error);
	 	});
	 	// oh no [ReferenceError: x is not defined]
	 	// carry on [ReferenceError: y is not defined]
	 	




	 	// 3、Promise.prototype.finally() 用于指定不管 Promise 对象状态如何，都会执行的操作。(ES2018引入标准)
	 	/*
	 	语法：
		 	promise
		 	.then(result => {...})
		 	.catch(error => {...})
		 	.finally(() => {...})
		*/
	



		// 4、Promise.prototype.all() 用于将多个 Promise 实例，包装成一个新的 Promise 实例,接受一个数组作为参数，数组内每一项都是 Promise 实例，如果不是，就会先调用 Promise.resolve方法，将参数转为 Promise 实例，再进一步处理
		const p9 = Promise.all([p1, p2, p3]);
		/*
		 注：
			1、只有p1、p2、p3的状态都变成fulfilled，p的状态才会变成fulfilled，此时p1、p2、p3的返回值组成一个数组，传递给p9的回调函数
			2、只要p1、p2、p3之中有一个被rejected，p9的状态就变成rejected，此时第一个被rejected实例的返回值，会传递给p9的回调函数
		*/



	</script>
	
</body>
</html>